<?xml version='1.0'?>
<sdf version='1.7'>
  <model name='A05_L50_K08'>

    <include>
      <uri>model://Base_Model</uri>
    </include>

    <link name='Leg_1'>
      <inertial>
        <mass>0.570e-3</mass>
        <pose>0 0 -0.025 0 0 0 </pose>
        <inertia>
          <ixx>155e-9</ixx>
          <ixy>0</ixy>
          <ixz>0</ixz>
          <iyy>155e-9</iyy>
          <iyz>0</iyz>
          <izz>2.5e-9</izz>
        </inertia>
      </inertial>
      <pose>2.07e-02 -2.07e-02 -3.25e-03 0 -0.087 -0.785</pose>
      <gravity>1</gravity>
      <self_collide>0</self_collide>
      <visual name='Leg_1_Visual'>
        <pose>0 0 0 0 0 0</pose>
        <geometry>
          <mesh>
            <uri>model://A05_L50_K08/meshes/LegConfig_A05_L50.STL</uri>
            <scale>1 1 1</scale>
          </mesh>
        </geometry>
        <material>
          <script>
            <name>Gazebo/Red </name>
            <uri>file://media/materials/scripts/gazebo.material</uri>
          </script>
          <lighting>1</lighting>
        </material>
      </visual>
      <collision name="Leg_1_Collision">
        <pose>0.004 0 -0.05 0 0 0</pose>        <!-- Position and orientation of the collision element -->
        <geometry>
          <sphere>
            <radius>0.002</radius>  <!-- Radius of the sphere -->
        </sphere>
        </geometry>
        <surface>
          <friction>
            <ode>
              <mu>1.0</mu>              <!-- Friction coefficient in the direction of the contact normal -->
              <mu2>1.0</mu2>              <!-- Friction coefficient in the tangent direction to the contact -->
            </ode>
          </friction>
          <contact>
            <ode>
              <soft_cfm>0</soft_cfm>              <!-- Constraint force mixing value -->
              <soft_erp>0.2</soft_erp>              <!-- Error reduction parameter value -->
            </ode>
          </contact>
        </surface>
      </collision>
    </link>

    <joint name="Hinge_1_Joint" type="revolute">
      <parent>Base_Model::SAR_Body</parent>
      <child>Leg_1</child>
      <pose>0 0 0 0 0 0</pose>
      <axis>
        <xyz>0 1 0</xyz>
        <limit>
          <lower>-100</lower>
          <upper>100</upper>
        </limit>
        <dynamics>
          <spring_stiffness>0.03</spring_stiffness>
          <damping>6.788e-05</damping>
        </dynamics>
      </axis>
    </joint>

    <plugin name='Leg_1_Plugin' filename='libSticky_Leg_Plugin.so'>
      <LegNumber>1</LegNumber>
      <linkName>Leg_1</linkName>
      <jointName>Leg_1_Joint</jointName>
      <collisionName>Leg_1_Collision</collisionName>
    </plugin>

    <static>0</static>
    <allow_auto_disable>1</allow_auto_disable>
  </model>
</sdf>
