<?xml version="1.0"?>
<sdf version='1.6'>
  <model name='crazyflie_landing_gears'>

    <link name='base_link'>
      <pose frame=''>0 0 0.030 0 -0 0</pose>
      <inertial>
        <pose frame=''>0 0 0 0 -0 0</pose>
        <mass>0.026</mass>
        <inertia>
          <ixx>1.65717e-05</ixx>
          <ixy>0</ixy>
          <ixz>0</ixz>
          <iyy>1.66556e-05</iyy>
          <iyz>0</iyz>
          <izz>2.92617e-05</izz>
        </inertia>
      </inertial>
      <collision name='base_link_inertia_collision'>
        <pose frame=''>0 0 0 0 -0 0</pose>
        <geometry>
          <box>
            <size>0.07 0.07 0.001</size>
          </box>
        </geometry>
        <surface>
          <contact>
            <ode>
              <min_depth>0.001</min_depth>
              <max_vel>0</max_vel>
            </ode>
          </contact>
          <friction>
            <ode/>
          </friction>
        </surface>
      </collision>
      <visual name='base_link_inertia_visual'>
        <pose frame=''>0 0 0 0 -0 0</pose>
        <geometry>
          <mesh>
            <scale>1 1 1</scale>
            <uri>model://crazyflie_landing_gears/meshes/crazyflie.dae</uri>
          </mesh>
        </geometry>
        <material>
          <script>
            <!-- <name>Gazebo/DarkGrey</name>
            <uri>file://media/materials/scripts/gazebo.material</uri> -->
          </script>
        </material>
      </visual>
      <gravity>1</gravity>
      <velocity_decay/>


    <sensor type="ray" name="head_hokuyo_sensor">
    <!-- Position the ray sensor based on the specification. Also rotate
       it by 90 degrees around the X-axis so that the <horizontal> rays
       become vertical -->
      <pose>0 0 0.01 0 -1.5707 0</pose>
      <!-- Enable visualization to see the rays in the GUI -->
        <visualize>true</visualize>
      <!-- Set the update rate of the sensor -->
      <update_rate>500</update_rate>
      <topicName>scan</topicName>
      <ray>
        <noise>
            <type>gaussian</type>
            <mean>0.0</mean>
            <stddev>0.05</stddev>
        </noise>
        <scan>
            <horizontal>
            <samples>1</samples>
            <!-- Resolution is multiplied by samples to determine number of
                simulated beams vs interpolated beams. See:
                http://sdformat.org/spec?ver=1.6&elem=sensor#horizontal_resolution
                -->
            <resolution>1</resolution>
            <min_angle>-0</min_angle>
            <max_angle>0</max_angle>
            </horizontal>
        </scan>
        <!-- Range defines characteristics of an individual beam -->
        <range>
            <min>0.04</min>
            <max>4</max>
           <resolution>0.02</resolution>
        </range>
       </ray>
       <plugin name="laser_back" filename="libgazebo_ros_laser.so">
            <!-- Publish within the robot namespace -->
            <!--robotNamespace>crazyflie</robotNamespace-->
            <topicName>zranger2/scan</topicName>
         </plugin>
     </sensor>

     <sensor type="camera" name="camera1">
     <pose>0 0 0.015 0 -1.5707 0</pose>
      <update_rate>500.0</update_rate>
      <camera name="head">
        <horizontal_fov>0.733038</horizontal_fov>
        <image>
          <width>36</width>
          <height>36</height>
          <format>R8G8B8</format>
        </image>
        <clip>
          <near>0.08</near>
          <far>300</far>
        </clip>
        <noise>
          <type>gaussian</type>
          <!-- Noise is sampled independently per pixel on each frame.
               That pixel's noise value is added to each of its color
               channels, which at that point lie in the range [0,1]. -->
          <mean>0.0</mean>
          <stddev>0.007</stddev>
        </noise>
      </camera>
      <plugin name="camera_controller" filename="libgazebo_ros_camera.so">
        <alwaysOn>true</alwaysOn>
        <updateRate>0.0</updateRate>
        <cameraName>camera</cameraName>
        <imageTopicName>image_raw</imageTopicName>
        <cameraInfoTopicName>camera_info</cameraInfoTopicName>
        <!--frameName>base_link</frameName-->
        <hackBaseline>0.07</hackBaseline>
        <distortionK1>0.0</distortionK1>
        <distortionK2>0.0</distortionK2>
        <distortionK3>0.0</distortionK3>
        <distortionT1>0.0</distortionT1>
        <distortionT2>0.0</distortionT2>
      </plugin>
    </sensor>
    
    </link>

    <link name='rotor_0'>
      <pose frame=''>0.032527 -0.032527 0.0425 0 -0 0</pose>
      <inertial>
        <pose frame=''>0 0 0 0 -0 0</pose>
        <mass>0.00075</mass>
        <inertia>
          <ixx>1.61875e-07</ixx>
          <ixy>0</ixy>
          <ixz>0</ixz>
          <iyy>8.86375e-06</iyy>
          <iyz>0</iyz>
          <izz>9.01687e-06</izz>
        </inertia>
      </inertial>
      <collision name='rotor_0_collision'>
        <pose frame=''>0 0 0 0 -0 0</pose>
        <geometry>
          <cylinder>
            <length>0.002</length>
            <radius>0.02</radius>
          </cylinder>
        </geometry>
        <surface>
          <contact>
            <ode/>
          </contact>
          <friction>
            <ode/>
          </friction>
        </surface>
      </collision>
      <visual name='rotor_0_visual'>
        <pose frame=''>0 0 0 0 -0 0</pose>
        <geometry>
          <mesh>
            <scale>1 1 1</scale>
            <uri>model://crazyflie_landing_gears/meshes/crazyflie_prop.dae</uri>
          </mesh>
        </geometry>
        <material>
          <script>
            <!-- <name>Gazebo/Blue</name> -->
            <!-- <uri>file://media/materials/scripts/gazebo.material</uri> -->
          </script>
        </material>
      </visual>
      <gravity>1</gravity>
      <velocity_decay/>
    </link>
    <joint name='rotor_0_joint' type='revolute'>
      <child>rotor_0</child>
      <parent>base_link</parent>
      <axis>
        <xyz>0 0 1</xyz>
        <limit>
          <lower>-1e+16</lower>
          <upper>1e+16</upper>
        </limit>
        <dynamics>
          <spring_reference>0</spring_reference>
          <spring_stiffness>0</spring_stiffness>
        </dynamics>
        <use_parent_model_frame>1</use_parent_model_frame>
      </axis>
    </joint>
    <link name='rotor_1'>
      <pose frame=''>-0.032527 0.032527 0.0425 0 -0 0</pose>
      <inertial>
        <pose frame=''>0 0 0 0 -0 0</pose>
        <mass>0.00075</mass>
        <inertia>
          <ixx>1.61875e-07</ixx>
          <ixy>0</ixy>
          <ixz>0</ixz>
          <iyy>8.86375e-06</iyy>
          <iyz>0</iyz>
          <izz>9.01687e-06</izz>
        </inertia>
      </inertial>
      <collision name='rotor_1_collision'>
        <pose frame=''>0 0 0 0 -0 0</pose>
        <geometry>
          <cylinder>
            <length>0.002</length>
            <radius>0.02</radius>
          </cylinder>
        </geometry>
        <surface>
          <contact>
            <ode/>
          </contact>
          <friction>
            <ode/>
          </friction>
        </surface>
      </collision>
      <visual name='rotor_1_visual'>
        <pose frame=''>0 0 0 0 -0 0</pose>
        <geometry>
          <mesh>
            <scale>1 1 1</scale>
            <uri>model://crazyflie_landing_gears/meshes/crazyflie_prop.dae</uri>
          </mesh>
        </geometry>
        <material>
          <script>
            <!-- <name>Gazebo/Blue</name> -->
            <!-- <uri>file://media/materials/scripts/gazebo.material</uri> -->
          </script>
        </material>
      </visual>
      <gravity>1</gravity>
      <velocity_decay/>
    </link>
    <joint name='rotor_1_joint' type='revolute'>
      <child>rotor_1</child>
      <parent>base_link</parent>
      <axis>
        <xyz>0 0 1</xyz>
        <limit>
          <lower>-1e+16</lower>
          <upper>1e+16</upper>
        </limit>
        <dynamics>
          <spring_reference>0</spring_reference>
          <spring_stiffness>0</spring_stiffness>
        </dynamics>
        <use_parent_model_frame>1</use_parent_model_frame>
      </axis>
    </joint>
    <link name='rotor_2'>
      <pose frame=''>0.032527 0.032527 0.0425 0 -0 0</pose>
      <inertial>
        <pose frame=''>0 0 0 0 -0 0</pose>
        <mass>0.00075</mass>
        <inertia>
          <ixx>1.61875e-07</ixx>
          <ixy>0</ixy>
          <ixz>0</ixz>
          <iyy>8.86375e-06</iyy>
          <iyz>0</iyz>
          <izz>9.01687e-06</izz>
        </inertia>
      </inertial>
      <collision name='rotor_2_collision'>
        <pose frame=''>0 0 0 0 -0 0</pose>
        <geometry>
          <cylinder>
            <length>0.002</length>
            <radius>0.02</radius>
          </cylinder>
        </geometry>
        <surface>
          <contact>
            <ode/>
          </contact>
          <friction>
            <ode/>
          </friction>
        </surface>
      </collision>
      <visual name='rotor_2_visual'>
        <pose frame=''>0 0 0 0 -0 0</pose>
        <geometry>
          <mesh>
            <scale>1 1 1</scale>
            <uri>model://crazyflie_landing_gears/meshes/crazyflie_prop.dae</uri>
          </mesh>
        </geometry>
        <material>
          <script>
            <!-- <name>Gazebo/DarkGrey</name> -->
            <!-- <uri>file://media/materials/scripts/gazebo.material</uri> -->
          </script>
        </material>
      </visual>
      <gravity>1</gravity>
      <velocity_decay/>
    </link>
    <joint name='rotor_2_joint' type='revolute'>
      <child>rotor_2</child>
      <parent>base_link</parent>
      <axis>
        <xyz>0 0 1</xyz>
        <limit>
          <lower>-1e+16</lower>
          <upper>1e+16</upper>
        </limit>
        <dynamics>
          <spring_reference>0</spring_reference>
          <spring_stiffness>0</spring_stiffness>
        </dynamics>
        <use_parent_model_frame>1</use_parent_model_frame>
      </axis>
    </joint>
    <link name='rotor_3'>
      <pose frame=''>-0.032527 -0.032527 0.0425 0 -0 0</pose>
      <inertial>
        <pose frame=''>0 0 0 0 -0 0</pose>
        <mass>0.00075</mass>
        <inertia>
          <ixx>1.61875e-07</ixx>
          <ixy>0</ixy>
          <ixz>0</ixz>
          <iyy>8.86375e-06</iyy>
          <iyz>0</iyz>
          <izz>9.01687e-06</izz>
        </inertia>
      </inertial>
      <collision name='rotor_3_collision'>
        <pose frame=''>0 0 0 0 -0 0</pose>
        <geometry>
          <cylinder>
            <length>0.002</length>
            <radius>0.02</radius>
          </cylinder>
        </geometry>
        <surface>
          <contact>
            <ode/>
          </contact>
          <friction>
            <ode/>
          </friction>
        </surface>
      </collision>
      <visual name='rotor_3_visual'>
        <pose frame=''>0 0 0 0 -0 0</pose>
        <geometry>
          <mesh>
            <scale>1 1 1</scale>
            <uri>model://crazyflie_landing_gears/meshes/crazyflie_prop.dae</uri>
          </mesh>
        </geometry>
        <material>
          <script>
            <!-- <name>Gazebo/DarkGrey</name> -->
            <!-- <uri>file://media/materials/scripts/gazebo.material</uri> -->
          </script>
        </material>
      </visual>
      <gravity>1</gravity>
      <velocity_decay/>
    </link>
    <joint name='rotor_3_joint' type='revolute'>
      <child>rotor_3</child>
      <parent>base_link</parent>
      <axis>
        <xyz>0 0 1</xyz>
        <limit>
          <lower>-1e+16</lower>
          <upper>1e+16</upper>
        </limit>
        <dynamics>
          <spring_reference>0</spring_reference>
          <spring_stiffness>0</spring_stiffness>
        </dynamics>
        <use_parent_model_frame>1</use_parent_model_frame>
      </axis>
    </joint>

    <!-- ======================= landing gears ======================= -->
    <!--landing gears 0-->
    <link name='landing_0'>
      <pose frame=''>0.026 0 0.014 0 -0.785 0</pose>
      <inertial>
        <pose frame=''>0 0 0 0 -0 0</pose>
        <mass>0.0004</mass>
        <inertia>
          <ixx>122.5e-9</ixx>
          <ixy>0</ixy>
          <ixz>0</ixz>
          <iyy>122.5e-9</iyy>
          <iyz>0</iyz>
          <izz>0.15e-9</izz>
        </inertia>
      </inertial>
      <collision name='landing_0_collision'>
        <pose frame=''>0 0 0 0 0 0</pose>
        <geometry>
          <cylinder>
            <length>0.04</length>
            <radius>0.0005</radius>
          </cylinder>
        </geometry>
        <surface>
          <bounce>
            <restitution_coefficient>0</restitution_coefficient>
            <threshold>1000000</threshold>
          </bounce>
          <contact>
            <ode>
              <min_depth>0.001</min_depth>
            </ode>
          </contact>
          <friction>
            <ode>
              <mu>100000</mu>
              <mu2>100000</mu2>
              <!--<fdir1>0 0 0</fdir1>
              <slip1>0</slip1>
              <slip2>0<slip2>-->
            </ode>
          </friction>
        </surface>
      </collision>
      <visual name='landing_0_visual'>
        <pose frame=''>0 0 0 0 0 0</pose>
        <geometry>
          <cylinder>
            <radius>0.001</radius>
            <length>0.04</length>
          </cylinder>
        </geometry>
        <material>
          <script>
            <name>Gazebo/Red</name>
            <uri>file://media/materials/scripts/gazebo.material</uri>
          </script>
        </material>
      </visual>
      <gravity>1</gravity>
      <velocity_decay/>
      <self_collide>0</self_collide>
    </link>
    <joint name='landing_0_joint' type='revolute'>
      <pose frame=''>0.012 0 0.029 0 0 0</pose>
      <child>landing_0</child>
      <parent>base_link</parent>
      <axis>
        <xyz>0 1 0</xyz>
        <limit>
          <lower>-0.7</lower>
          <upper>0.7</upper>
          <effort>1e-5</effort>
          <velocity>0</velocity>
        </limit>
        <dynamics>
          <damping>1e-5</damping>
          <friction>1e-6</friction>
          <spring_reference>0</spring_reference>
          <spring_stiffness>2e-2</spring_stiffness>
        </dynamics>
        <use_parent_model_frame>1</use_parent_model_frame>
      </axis>
      <physics>
        <ode>
          <erp>0.2</erp>
        </ode>
      </physics>
    </joint>

    <!--landing gears 1-->
    <link name='landing_1'>
      <pose frame=''>0 0.026 0.014 0.785 0 0</pose>
      <inertial>
        <pose frame=''>0 0 0 0 -0 0</pose>
        <mass>0.0004</mass>
        <inertia>
          <ixx>122.5e-9</ixx>
          <ixy>0</ixy>
          <ixz>0</ixz>
          <iyy>122.5e-9</iyy>
          <iyz>0</iyz>
          <izz>0.15e-9</izz>
        </inertia>
      </inertial>
      <collision name='landing_1_collision'>
        <pose frame=''>0 0 0 0 0 0</pose>
        <geometry>
          <cylinder>
            <length>0.04</length>
            <radius>0.0005</radius>
          </cylinder>
        </geometry>
        <surface>
          <bounce>
            <restitution_coefficient>0</restitution_coefficient>
            <threshold>1000000</threshold>
          </bounce>
          <contact>
            <ode>
              <min_depth>0.001</min_depth>
            </ode>
          </contact>
          <friction>
            <ode>
              <mu>100000</mu>
              <mu2>100000</mu2>
              <!--<fdir1>0 0 0</fdir1>
              <slip1>0</slip1>
              <slip2>0<slip2>-->
            </ode>
          </friction>
        </surface>
      </collision>
      <visual name='landing_1_visual'>
        <pose frame=''>0 0 0 0 0 0</pose>
        <geometry>
          <cylinder>
            <radius>0.001</radius>
            <length>0.04</length>
          </cylinder>
        </geometry>
        <material>
          <script>
            <name>Gazebo/White</name>
            <uri>file://media/materials/scripts/gazebo.material</uri>
          </script>
        </material>
      </visual>
      <gravity>1</gravity>
      <velocity_decay/>
      <self_collide>0</self_collide>
    </link>
    <joint name='landing_1_joint' type='revolute'>
      <pose frame=''>0 0.012 0.029 0 0 0</pose>
      <child>landing_1</child>
      <parent>base_link</parent>
      <axis>
        <xyz>1 0 0</xyz>
        <limit>
          <lower>-0.7</lower>
          <upper>0.7</upper>
          <effort>1e-5</effort>
          <velocity>0</velocity>
        </limit>
        <dynamics>
          <damping>1e-5</damping>
          <friction>1e-6</friction>
          <spring_reference>0</spring_reference>
          <spring_stiffness>2e-2</spring_stiffness>
        </dynamics>
        <use_parent_model_frame>1</use_parent_model_frame>
      </axis>
      <physics>
        <ode>
          <erp>0.2</erp>
        </ode>
      </physics>
    </joint>

    <!--landing gears 2-->
    <link name='landing_2'>
      <pose frame=''>-0.026 0 0.014 0 0.785 0</pose>
      <inertial>
        <pose frame=''>0 0 0 0 -0 0</pose>
        <mass>0.0004</mass>
        <inertia>
          <ixx>122.5e-9</ixx>
          <ixy>0</ixy>
          <ixz>0</ixz>
          <iyy>122.5e-9</iyy>
          <iyz>0</iyz>
          <izz>0.15e-9</izz>
        </inertia>
      </inertial>
      <collision name='landing_2_collision'>
        <pose frame=''>0 0 0 0 0 0</pose>
        <geometry>
          <cylinder>
            <length>0.04</length>
            <radius>0.0005</radius>
          </cylinder>
        </geometry>
        <surface>
          <bounce>
            <restitution_coefficient>0</restitution_coefficient>
            <threshold>1000000</threshold>
          </bounce>
          <contact>
            <ode>
              <min_depth>0.001</min_depth>
            </ode>
          </contact>
          <friction>
            <ode>
              <mu>100000</mu>
              <mu2>100000</mu2>
              <!--<fdir1>0 0 0</fdir1>
              <slip1>0</slip1>
              <slip2>0<slip2>-->
            </ode>
          </friction>
        </surface>
      </collision>
      <visual name='landing_2_visual'>
        <pose frame=''>0 0 0 0 0 0</pose>
        <geometry>
          <cylinder>
            <radius>0.001</radius>
            <length>0.04</length>
          </cylinder>
        </geometry>
        <material>
          <script>
            <name>Gazebo/White</name>
            <uri>file://media/materials/scripts/gazebo.material</uri>
          </script>
        </material>
      </visual>
      <gravity>1</gravity>
      <velocity_decay/>
      <self_collide>0</self_collide>
    </link>
    <joint name='landing_2_joint' type='revolute'>
      <pose frame=''>-0.012 0 0.029 0 0 0</pose>
      <child>landing_2</child>
      <parent>base_link</parent>
      <axis>
        <xyz>0 1 0</xyz>
        <limit>
          <lower>-0.7</lower>
          <upper>0.7</upper>
          <effort>1e-5</effort>
          <velocity>0</velocity>
        </limit>
        <dynamics>
          <damping>1e-5</damping>
          <friction>1e-6</friction>
          <spring_reference>0</spring_reference>
          <spring_stiffness>2e-2</spring_stiffness>
        </dynamics>
        <use_parent_model_frame>1</use_parent_model_frame>
      </axis>
      <physics>
        <ode>
          <erp>0.2</erp>
        </ode>
      </physics>
    </joint>

    <!--landing gears 3-->
    <link name='landing_3'>
      <pose frame=''>0 -0.026 0.014 -0.785 0 0</pose>
      <inertial>
        <pose frame=''>0 0 0 0 -0 0</pose>
        <mass>0.0004</mass>
        <inertia>
          <ixx>122.5e-9</ixx>
          <ixy>0</ixy>
          <ixz>0</ixz>
          <iyy>122.5e-9</iyy>
          <iyz>0</iyz>
          <izz>0.15e-9</izz>
        </inertia>
      </inertial>
      <collision name='landing_3_collision'>
        <pose frame=''>0 0 0 0 0 0</pose>
        <geometry>
          <cylinder>
            <length>0.04</length>
            <radius>0.0005</radius>
          </cylinder>
        </geometry>
        <surface>
          <bounce>
            <restitution_coefficient>0</restitution_coefficient>
            <threshold>1000000</threshold>
          </bounce>
          <contact>
            <ode>
              <min_depth>0.001</min_depth>
            </ode>
          </contact>
          <friction>
            <ode>
              <mu>100000</mu>
              <mu2>100000</mu2>
              <!--<fdir1>0 0 0</fdir1>
              <slip1>0</slip1>
              <slip2>0<slip2>-->
            </ode>
          </friction>
        </surface>
      </collision>
      <visual name='landing_3_visual'>
        <pose frame=''>0 0 0 0 0 0</pose>
        <geometry>
          <cylinder>
            <radius>0.001</radius>
            <length>0.04</length>
          </cylinder>
        </geometry>
        <material>
          <script>
            <name>Gazebo/White</name>
            <uri>file://media/materials/scripts/gazebo.material</uri>
          </script>
        </material>
      </visual>
      <gravity>1</gravity>
      <velocity_decay/>
      <self_collide>0</self_collide>
    </link>
    <joint name='landing_3_joint' type='revolute'>
      <pose frame=''>0 -0.012 0.029 0 0 0</pose>
      <child>landing_3</child>
      <parent>base_link</parent>
      <axis>
        <xyz>1 0 0</xyz>
        <limit>
          <lower>-0.7</lower>
          <upper>0.7</upper>
          <effort>1e-5</effort>
          <velocity>0</velocity>
        </limit>
        <dynamics>
          <damping>1e-5</damping>
          <friction>1e-6</friction>
          <spring_reference>0</spring_reference>
          <spring_stiffness>2e-2</spring_stiffness>
        </dynamics>
        <use_parent_model_frame>1</use_parent_model_frame>
      </axis>
      <physics>
        <ode>
          <erp>0.2</erp>
        </ode>
      </physics>
    </joint>

      <!--pad 0 for landing gears 0-->
    <link name='pad_0'>
      <pose frame=''>0.040 0.0 0 0 0 0</pose>
      <inertial>
        <pose frame=''>0 0 0 0 -0 0</pose>
        <mass>0.0001</mass>
        <inertia>
          <ixx>2.5e-9</ixx>
          <ixy>0</ixy>
          <ixz>0</ixz>
          <iyy>2.5e-9</iyy>
          <iyz>0</iyz>
          <izz>5e-9</izz>
        </inertia>
      </inertial>
      <collision name='pad_0_collision'>
        <pose frame=''>0 0 0 0 0 0</pose>
        <geometry>
          <cylinder>
            <length>0.0005</length>
            <radius>0.001</radius>
          </cylinder>
        </geometry>
        <surface>
          <bounce>
            <restitution_coefficient>0</restitution_coefficient>
            <threshold>1000000</threshold>
          </bounce>
          <contact>
            <ode>
              <min_depth>0.001</min_depth>
            </ode>
          </contact>
          <friction>
            <ode>
              <mu>100000</mu>
              <mu2>100000</mu2>
            </ode>
          </friction>
        </surface>
      </collision>
      <visual name='pad_0_visual'>
        <pose frame=''>0 0 0 0 0 0</pose>
        <geometry>
          <cylinder>
            <length>0.0005</length>
            <radius>0.001</radius>
          </cylinder>
        </geometry>
        <material>
          <script>
            <name>Gazebo/Red</name>
            <uri>file://media/materials/scripts/gazebo.material</uri>
          </script>
        </material>
      </visual>
      <gravity>1</gravity>
      <velocity_decay/>
      <self_collide>0</self_collide>
    </link>
    <joint name='pad_0_joint' type='ball'>
      <child>pad_0</child>
      <parent>landing_0</parent>
    </joint>

    <!--pad 1 for landing gears 1-->
    <link name='pad_1'>
      <pose frame=''>0 0.040 0 0 0 0</pose>
      <inertial>
        <pose frame=''>0 0 0 0 -0 0</pose>
        <mass>0.0001</mass>
        <inertia>
          <ixx>2.5e-9</ixx>
          <ixy>0</ixy>
          <ixz>0</ixz>
          <iyy>2.5e-9</iyy>
          <iyz>0</iyz>
          <izz>5e-9</izz>
        </inertia>
      </inertial>
      <collision name='pad_1_collision'>
        <pose frame=''>0 0 0 0 0 0</pose>
        <geometry>
          <cylinder>
            <length>0.0005</length>
            <radius>0.001</radius>
          </cylinder>
        </geometry>
        <surface>
          <bounce>
            <restitution_coefficient>0</restitution_coefficient>
            <threshold>1000000</threshold>
          </bounce>
          <contact>
            <ode>
              <min_depth>0.001</min_depth>
            </ode>
          </contact>
          <friction>
            <ode>
              <mu>100000</mu>
              <mu2>100000</mu2>
            </ode>
          </friction>
        </surface>
      </collision>
      <visual name='pad_1_visual'>
        <pose frame=''>0 0 0 0 0 0</pose>
        <geometry>
          <cylinder>
            <length>0.0005</length>
            <radius>0.001</radius>
          </cylinder>
        </geometry>
        <material>
          <script>
            <name>Gazebo/White</name>
            <uri>file://media/materials/scripts/gazebo.material</uri>
          </script>
        </material>
      </visual>
      <gravity>1</gravity>
      <velocity_decay/>
      <self_collide>0</self_collide>
    </link>
    <joint name='pad_1_joint' type='ball'>
      <child>pad_1</child>
      <parent>landing_1</parent>
    </joint>

    <!--pad 2 for landing gears 2-->
    <link name='pad_2'>
      <pose frame=''>-0.040 0 0 0 0 0</pose>
      <inertial>
        <pose frame=''>0 0 0 0 -0 0</pose>
        <mass>0.0001</mass>
        <inertia>
          <ixx>2.5e-9</ixx>
          <ixy>0</ixy>
          <ixz>0</ixz>
          <iyy>2.5e-9</iyy>
          <iyz>0</iyz>
          <izz>5e-9</izz>
        </inertia>
      </inertial>
      <collision name='pad_2_collision'>
        <pose frame=''>0 0 0 0 0 0</pose>
        <geometry>
          <cylinder>
            <length>0.0005</length>
            <radius>0.001</radius>
          </cylinder>
        </geometry>
        <surface>
          <bounce>
            <restitution_coefficient>0</restitution_coefficient>
            <threshold>1000000</threshold>
          </bounce>
          <contact>
            <ode>
              <min_depth>0.001</min_depth>
            </ode>
          </contact>
          <friction>
            <ode>
              <mu>100000</mu>
              <mu2>100000</mu2>
            </ode>
          </friction>
        </surface>
      </collision>
      <visual name='pad_2_visual'>
        <pose frame=''>0 0 0 0 0 0</pose>
        <geometry>
          <cylinder>
            <length>0.0005</length>
            <radius>0.001</radius>
          </cylinder>
        </geometry>
        <material>
          <script>
            <name>Gazebo/White</name>
            <uri>file://media/materials/scripts/gazebo.material</uri>
          </script>
        </material>
      </visual>
      <gravity>1</gravity>
      <velocity_decay/>
      <self_collide>0</self_collide>
    </link>
    <joint name='pad_2_joint' type='ball'>
      <child>pad_2</child>
      <parent>landing_2</parent>
    </joint>

    <!--pad 3 for landing gears 3-->
    <link name='pad_3'>
      <pose frame=''>0 -0.040 0 0 0 0</pose>
      <inertial>
        <pose frame=''>0 0 0 0 -0 0</pose>
        <mass>0.0001</mass>
        <inertia>
          <ixx>2.5e-9</ixx>
          <ixy>0</ixy>
          <ixz>0</ixz>
          <iyy>2.5e-9</iyy>
          <iyz>0</iyz>
          <izz>5e-9</izz>
        </inertia>
      </inertial>
      <collision name='pad_3_collision'>
        <pose frame=''>0 0 0 0 0 0</pose>
        <geometry>
          <cylinder>
            <length>0.0005</length>
            <radius>0.001</radius>
          </cylinder>
        </geometry>
        <surface>
          <bounce>
            <restitution_coefficient>0</restitution_coefficient>
            <threshold>1000000</threshold>
          </bounce>
          <contact>
            <ode>
              <min_depth>0.001</min_depth>
            </ode>
          </contact>
          <friction>
            <ode>
              <mu>100000</mu>
              <mu2>100000</mu2>
            </ode>
          </friction>
        </surface>
      </collision>
      <visual name='pad_3_visual'>
        <pose frame=''>0 0 0 0 0 0</pose>
        <geometry>
          <cylinder>
            <length>0.0005</length>
            <radius>0.001</radius>
          </cylinder>
        </geometry>
        <material>
          <script>
            <name>Gazebo/White</name>
            <uri>file://media/materials/scripts/gazebo.material</uri>
          </script>
        </material>
      </visual>
      <gravity>1</gravity>
      <velocity_decay/>
      <self_collide>0</self_collide>
    </link>
    <joint name='pad_3_joint' type='ball'>
      <child>pad_3</child>
      <parent>landing_3</parent>
    </joint>


    <!-- ======================= plugins ======================= -->
    <plugin name='front_right_motor_model' filename='libgazebo_motor_model.so'>
      <robotNamespace/>
      <jointName>rotor_0_joint</jointName>
      <linkName>rotor_0</linkName>
      <turningDirection>ccw</turningDirection>
      <timeConstantUp>0.0001</timeConstantUp>
      <timeConstantDown>0.0001</timeConstantDown>
      <maxRotVelocity>3052</maxRotVelocity>
      <motorConstant>1.2819184e-08</motorConstant>
      <momentConstant>0.005964552</momentConstant>
      <commandSubTopic>/gazebo/command/motor_speed</commandSubTopic>
      <motorNumber>0</motorNumber>
      <rotorDragCoefficient>9.1785e-07</rotorDragCoefficient>
      <rollingMomentCoefficient>1e-07</rollingMomentCoefficient>
      <motorSpeedPubTopic>/motor_speed/0</motorSpeedPubTopic>
      <rotorVelocitySlowdownSim>20</rotorVelocitySlowdownSim>
    </plugin>
    <plugin name='back_left_motor_model' filename='libgazebo_motor_model.so'>
      <robotNamespace/>
      <jointName>rotor_1_joint</jointName>
      <linkName>rotor_1</linkName>
      <turningDirection>ccw</turningDirection>
      <timeConstantUp>0.0001</timeConstantUp>
      <timeConstantDown>0.0001</timeConstantDown>
      <maxRotVelocity>3052</maxRotVelocity>
      <motorConstant>1.2819184e-08</motorConstant>
      <momentConstant>0.005964552</momentConstant>
      <commandSubTopic>/gazebo/command/motor_speed</commandSubTopic>
      <motorNumber>1</motorNumber>
      <rotorDragCoefficient>9.1785e-07</rotorDragCoefficient>
      <rollingMomentCoefficient>1e-07</rollingMomentCoefficient>
      <motorSpeedPubTopic>/motor_speed/1</motorSpeedPubTopic>
      <rotorVelocitySlowdownSim>20</rotorVelocitySlowdownSim>
    </plugin>
    <plugin name='front_left_motor_model' filename='libgazebo_motor_model.so'>
      <robotNamespace/>
      <jointName>rotor_2_joint</jointName>
      <linkName>rotor_2</linkName>
      <turningDirection>cw</turningDirection>
      <timeConstantUp>0.0001</timeConstantUp>
      <timeConstantDown>0.0001</timeConstantDown>
      <maxRotVelocity>3052</maxRotVelocity>
      <motorConstant>1.2819184e-08</motorConstant>
      <momentConstant>0.005964552</momentConstant>
      <commandSubTopic>/gazebo/command/motor_speed</commandSubTopic>
      <motorNumber>2</motorNumber>
      <rotorDragCoefficient>9.1785e-07</rotorDragCoefficient>
      <rollingMomentCoefficient>1e-07</rollingMomentCoefficient>
      <motorSpeedPubTopic>/motor_speed/2</motorSpeedPubTopic>
      <rotorVelocitySlowdownSim>20</rotorVelocitySlowdownSim>
    </plugin>
    <plugin name='back_right_motor_model' filename='libgazebo_motor_model.so'>
      <robotNamespace/>
      <jointName>rotor_3_joint</jointName>
      <linkName>rotor_3</linkName>
      <turningDirection>cw</turningDirection>
      <timeConstantUp>0.0001</timeConstantUp>
      <timeConstantDown>0.0001</timeConstantDown>
      <maxRotVelocity>3052</maxRotVelocity>
      <motorConstant>1.2819184e-08</motorConstant>
      <momentConstant>0.005964552</momentConstant>
      <commandSubTopic>/gazebo/command/motor_speed</commandSubTopic>
      <motorNumber>3</motorNumber>
      <rotorDragCoefficient>9.1785e-07</rotorDragCoefficient>
      <rollingMomentCoefficient>1e-07</rollingMomentCoefficient>
      <motorSpeedPubTopic>/motor_speed/3</motorSpeedPubTopic>
      <rotorVelocitySlowdownSim>20</rotorVelocitySlowdownSim>
    </plugin>
    <plugin name='mavlink' filename='libgazebo_mavlink.so'>
      <robotNamespace/>
      <linkName>base_link</linkName>
      <mavlink_addr>INADDR_ANY</mavlink_addr>
      <mavlink_port>18080</mavlink_port>
      <motorSpeedCommandPubTopic>/gazebo/command/motor_speed</motorSpeedCommandPubTopic>
      <stickyEnablePubTopic>/gazebo/command/sticky_enable</stickyEnablePubTopic>
    </plugin>

    <plugin name='pad_0_sticky' filename='libgazebo_sticky_foot.so'>
      <robotNamespace/>
      <linkName>pad_0</linkName>
      <padNumber>0</padNumber>
      <stickyEnableSubTopic>/gazebo/command/sticky_enable</stickyEnableSubTopic>
      <maxUpVelocity>100</maxUpVelocity>
    </plugin>
    <plugin name='pad_1_sticky' filename='libgazebo_sticky_foot.so'>
      <robotNamespace/>
      <linkName>pad_1</linkName>
      <padNumber>1</padNumber>
      <stickyEnableSubTopic>/gazebo/command/sticky_enable</stickyEnableSubTopic>
      <maxUpVelocity>100</maxUpVelocity>
    </plugin>
    <plugin name='pad_2_sticky' filename='libgazebo_sticky_foot.so'>
      <robotNamespace/>
      <linkName>pad_2</linkName>
      <padNumber>2</padNumber>
      <stickyEnableSubTopic>/gazebo/command/sticky_enable</stickyEnableSubTopic>
      <maxUpVelocity>100</maxUpVelocity>
    </plugin>
    <plugin name='pad_3_sticky' filename='libgazebo_sticky_foot.so'>
      <robotNamespace/>
      <linkName>pad_3</linkName>
      <padNumber>3</padNumber>
      <stickyEnableSubTopic>/gazebo/command/sticky_enable</stickyEnableSubTopic>
      <maxUpVelocity>100</maxUpVelocity>
    </plugin>
  </model>
</sdf>
