<?xml version='1.0'?>
<sdf version='1.7'>
  <model name='A30_L200'>

    <!-- <include>
      <uri>model://SAR_Base</uri>
    </include> -->

    <link name='Leg_1'>
      <pose>0 0 0 0 0 0</pose>
      <inertial>
        <mass>5.9e-3</mass>
        <pose>0 0 0 0 0 0 </pose>
        <inertia>
          <ixx>19.667e-6</ixx>
          <ixy>0</ixy>
          <ixz>0</ixz>
          <iyy>19.667e-6</iyy>
          <iyz>0</iyz>
          <izz>18.4375e-9</izz>
        </inertia>
      </inertial>
      <gravity>1</gravity>
      <self_collide>0</self_collide>
      <visual name='Leg_Visual'>
        <pose>0 0 0 0 0 0</pose>
        <geometry>
          <cylinder>
            <radius>2.5e-3</radius>
            <length>200.0e-3</length>
          </cylinder>

        </geometry>
        <material>
          <script>
            <name>Gazebo/Red </name>
            <uri>file://media/materials/scripts/gazebo.material</uri>
          </script>
          <lighting>1</lighting>
        </material>
      </visual>
    </link>




    <joint name='Hinge_Joint' type='revolute'>
      <parent>world</parent>
      <child>Leg_1</child>
      <pose>0 0 0 0 0 0</pose>
        <axis>
          <xyz>0 1 0</xyz>
          <limit>
            <lower>-3.0</lower>
            <upper>3.0</upper>
            <effort>-1</effort>
            <velocity>-1</velocity>
          </limit>
          <dynamics>
            <spring_stiffness>0.001</spring_stiffness>
          </dynamics>
        </axis>
    </joint> 


    

    <static>0</static>
    <allow_auto_disable>1</allow_auto_disable>
  </model>
</sdf>
