<?xml version='1.0'?>
<sdf version='1.7'>
  <model name='A30_L200'>

    <include>
      <uri>model://SAR_Base</uri>
    </include>

    <link name='Leg_1'>
      <pose>18.5e-3 -18.5e-3 -4.0e-3 0 1.047 -0.785</pose>
      <inertial>
        <mass>18.12e-3</mass>
        <pose>107.66e-3 0 2.36e-3 0 0 0 </pose>
        <inertia>
          <ixx>1.03e-6</ixx>
          <ixy>0</ixy>
          <ixz>3.61e-6</ixz>
          <iyy>8.25e-5</iyy>
          <iyz>0</iyz>
          <izz>8.18e-5</izz>
        </inertia>
      </inertial>
      <gravity>1</gravity>
      <self_collide>0</self_collide>
      <visual name='Leg_Visual'>
        <pose>0 0 0 0 0 0</pose>
        <geometry>
          <mesh>
            <uri>model://Leg_Assemblies/meshes/Leg_Assembly_30_deg--150mm.STL</uri>
            <scale>1 1 1</scale>
          </mesh>
        </geometry>
        <material>
          <script>
            <name>Gazebo/Red </name>
            <uri>file://media/materials/scripts/gazebo.material</uri>
          </script>
          <lighting>1</lighting>
        </material>
      </visual>
    </link>




    <joint name='Hinge_Joint' type='revolute'>
      <parent>SAR_Base::SAR_Body</parent>
      <child>Leg_1</child>
      <pose>0 0 0 0 0 0</pose>
        <axis>
          <xyz>0 1 0</xyz>
          <limit>
            <lower>-3.0</lower>
            <upper>3.0</upper>
            <effort>-1</effort>
            <velocity>-1</velocity>
          </limit>
          <dynamics>
            <spring_stiffness>0.01157</spring_stiffness>
          </dynamics>
        </axis>
    </joint> 

    <!-- <joint name='Hinge_1_Joint' type='universal'>
      <parent>SAR_Base::SAR_Body</parent>
      <child>Leg_1</child>
      <pose>0 0 0 0 0 0</pose>
      <axis>
        <xyz>0 1 0</xyz>
        <limit>
          <lower>-0.785</lower>
          <upper>0.524</upper>
        </limit>
        <dynamics>
          <spring_stiffness>0</spring_stiffness>
          <damping>0</damping>
        </dynamics>
      </axis>
      <axis2>
        <xyz>0 0 1</xyz>
        <limit>
          <lower>-0.5</lower>
          <upper>0.5</upper>
        </limit>
        <dynamics>
          <spring_stiffness>0</spring_stiffness>
          <damping>0</damping>
        </dynamics>
      </axis2>
    </joint> -->


    

    <static>0</static>
    <allow_auto_disable>1</allow_auto_disable>
  </model>
</sdf>
