<?xml version="1.0" ?>
<!-- =================================================================================== -->
<!-- |    This document was autogenerated by xacro from Source_One.xacro               | -->
<!-- |    EDITING THIS FILE BY HAND IS NOT RECOMMENDED                                 | -->
<!-- =================================================================================== -->
<!-- Revolute-Revolute Manipulator -->
<robot name="Source_One">
  <!-- ros_control plugin -->
  <gazebo>
    <plugin filename="libgazebo_ros_control.so" name="gazebo_ros_control">
      <robotNamespace>/Source_One</robotNamespace>
      <robotSimType>gazebo_ros_control/DefaultRobotHWSim</robotSimType>
    </plugin>
  </gazebo>
  <!-- SAR_Body -->
  <gazebo reference="SAR_Body">
    <material>Gazebo/DarkGrey</material>
  </gazebo>
  <gazebo reference="Prop_Guards">
    <material>Gazebo/White</material>
  </gazebo>
  <gazebo reference="Prop_1">
    <material>Gazebo/BlueTransparent</material>
  </gazebo>
  <gazebo reference="Prop_2">
    <material>Gazebo/BlueTransparent</material>
  </gazebo>
  <gazebo reference="Prop_3">
    <material>Gazebo/BlueTransparent</material>
  </gazebo>
  <gazebo reference="Prop_4">
    <material>Gazebo/BlueTransparent</material>
  </gazebo>
  <gazebo reference="Leg_1">
    <material>Gazebo/Red</material>
  </gazebo>
  <gazebo reference="Leg_2">
    <material>Gazebo/DarkGrey</material>
  </gazebo>
  <gazebo reference="Leg_3">
    <material>Gazebo/DarkGrey</material>
  </gazebo>
  <gazebo reference="Leg_4">
    <material>Gazebo/Red</material>
  </gazebo>
  <gazebo reference="camera_link">
    <material>Gazebo/Grey</material>
  </gazebo>
  <gazebo>
    <plugin filename="libMotor_Plugin.so" name="Motor_1_Plugin">
      <Motor_Number>1</Motor_Number>
      <Joint_Name>Prop_1_Joint</Joint_Name>
      <Link_Name>Prop_1</Link_Name>
      <Turning_Direction>ccw</Turning_Direction>
      <Visual_Slowdown>200</Visual_Slowdown>
    </plugin>
  </gazebo>
  <gazebo>
    <plugin filename="libMotor_Plugin.so" name="Motor_2_Plugin">
      <Motor_Number>2</Motor_Number>
      <Joint_Name>Prop_2_Joint</Joint_Name>
      <Link_Name>Prop_2</Link_Name>
      <Turning_Direction>cw</Turning_Direction>
      <Visual_Slowdown>200</Visual_Slowdown>
    </plugin>
  </gazebo>
  <gazebo>
    <plugin filename="libMotor_Plugin.so" name="Motor_3_Plugin">
      <Motor_Number>3</Motor_Number>
      <Joint_Name>Prop_3_Joint</Joint_Name>
      <Link_Name>Prop_3</Link_Name>
      <Turning_Direction>ccw</Turning_Direction>
      <Visual_Slowdown>200</Visual_Slowdown>
    </plugin>
  </gazebo>
  <gazebo>
    <plugin filename="libMotor_Plugin.so" name="Motor_4_Plugin">
      <Motor_Number>4</Motor_Number>
      <Joint_Name>Prop_4_Joint</Joint_Name>
      <Link_Name>Prop_4</Link_Name>
      <Turning_Direction>cw</Turning_Direction>
      <Visual_Slowdown>200</Visual_Slowdown>
    </plugin>
  </gazebo>
  <gazebo reference="Leg_1">
    <sensor name="Contact_Sensor" type="contact">
      <contact>
        <collision>Leg_1_collision</collision>
      </contact>
      <update_rate>1000</update_rate>
      <alwaysOn>true</alwaysOn>
    </sensor>
  </gazebo>
  <gazebo reference="Hinge_1_Joint">
    <preserveFixedJoint>true</preserveFixedJoint>
  </gazebo>
  <gazebo>
    <plugin filename="libSticky_Leg_Plugin.so" name="Leg_1_Plugin">
      <LegNumber>1</LegNumber>
      <LinkName>Leg_1</LinkName>
      <CollisionName>Leg_1_collision</CollisionName>
      <JointName>Leg_1_Contact_Joint</JointName>
    </plugin>
  </gazebo>
  <gazebo reference="Leg_2">
    <sensor name="Contact_Sensor" type="contact">
      <contact>
        <collision>Leg_2_collision</collision>
      </contact>
      <update_rate>1000</update_rate>
      <alwaysOn>true</alwaysOn>
    </sensor>
  </gazebo>
  <gazebo reference="Hinge_2_Joint">
    <preserveFixedJoint>true</preserveFixedJoint>
  </gazebo>
  <gazebo>
    <plugin filename="libSticky_Leg_Plugin.so" name="Leg_2_Plugin">
      <LegNumber>1</LegNumber>
      <LinkName>Leg_2</LinkName>
      <CollisionName>Leg_2_collision</CollisionName>
      <JointName>Leg_2_Contact_Joint</JointName>
    </plugin>
  </gazebo>
  <gazebo reference="Leg_3">
    <sensor name="Contact_Sensor" type="contact">
      <contact>
        <collision>Leg_3_collision</collision>
      </contact>
      <update_rate>1000</update_rate>
      <alwaysOn>true</alwaysOn>
    </sensor>
  </gazebo>
  <gazebo reference="Hinge_3_Joint">
    <preserveFixedJoint>true</preserveFixedJoint>
  </gazebo>
  <gazebo>
    <plugin filename="libSticky_Leg_Plugin.so" name="Leg_3_Plugin">
      <LegNumber>1</LegNumber>
      <LinkName>Leg_3</LinkName>
      <CollisionName>Leg_3_collision</CollisionName>
      <JointName>Leg_3_Contact_Joint</JointName>
    </plugin>
  </gazebo>
  <gazebo reference="Leg_4">
    <sensor name="Contact_Sensor" type="contact">
      <contact>
        <collision>Leg_4_collision</collision>
      </contact>
      <update_rate>1000</update_rate>
      <alwaysOn>true</alwaysOn>
    </sensor>
  </gazebo>
  <gazebo reference="Hinge_4_Joint">
    <preserveFixedJoint>true</preserveFixedJoint>
  </gazebo>
  <gazebo>
    <plugin filename="libSticky_Leg_Plugin.so" name="Leg_4_Plugin">
      <LegNumber>4</LegNumber>
      <LinkName>Leg_4</LinkName>
      <CollisionName>Leg_4_collision</CollisionName>
      <JointName>Leg_4_Contact_Joint</JointName>
    </plugin>
  </gazebo>
  <gazebo>
    <plugin filename="libSAR_Update_Plugin.so" name="SAR_Update_Plugin">
    </plugin>
  </gazebo>
  <gazebo>
    <plugin filename="libgazebo_ros_p3d.so" name="Vicon_plugin">
      <alwaysOn>true</alwaysOn>
      <updateRate>1000</updateRate>
      <bodyName>SAR_Body</bodyName>
      <topicName>SAR_External/ExtPosition</topicName>
      <frameName>world</frameName>
      <xyzOffsets>0 0 0</xyzOffsets>
      <rpyOffsets>0 0 0</rpyOffsets>
      <robotNamespace>/</robotNamespace>
    </plugin>
  </gazebo>
  <gazebo>
    <plugin filename="libgazebo_ros_imu.so" name="IMU_plugin">
      <alwaysOn>true</alwaysOn>
      <updateRate>1000</updateRate>
      <bodyName>SAR_Body</bodyName>
      <topicName>SAR_Internal/IMU</topicName>
      <serviceName>imu_service</serviceName>
      <frameName>SAR_Body</frameName>
    </plugin>
  </gazebo>
  <!-- camera -->
  <gazebo reference="camera_link">
    <sensor name="camera1" type="camera">
      <update_rate>30.0</update_rate>
      <camera name="head">
        <horizontal_fov>1.3962634</horizontal_fov>
        <image>
          <width>640</width>
          <height>640</height>
          <format>R8G8B8</format>
        </image>
        <clip>
          <near>0.02</near>
          <far>100</far>
        </clip>
        <noise>
          <type>gaussian</type>
          <!-- Noise is sampled independently per pixel on each frame.
               That pixel's noise value is added to each of its color
               channels, which at that point lie in the range [0,1]. -->
          <mean>0.0</mean>
          <stddev>0.00</stddev>
        </noise>
      </camera>
      <plugin filename="libgazebo_ros_camera.so" name="camera_controller">
        <alwaysOn>true</alwaysOn>
        <updateRate>0.0</updateRate>
        <cameraName>SAR_Internal/camera</cameraName>
        <imageTopicName>image_raw</imageTopicName>
        <cameraInfoTopicName>camera_info</cameraInfoTopicName>
        <frameName>camera_link_optical</frameName>
        <!-- setting hackBaseline to anything but 0.0 will cause a misalignment
            between the gazebo sensor image and the frame it is supposed to
            be attached to -->
        <hackBaseline>0.0</hackBaseline>
        <distortionK1>0.0</distortionK1>
        <distortionK2>0.0</distortionK2>
        <distortionK3>0.0</distortionK3>
        <distortionT1>0.0</distortionT1>
        <distortionT2>0.0</distortionT2>
        <CxPrime>0</CxPrime>
        <Cx>0.0</Cx>
        <Cy>0.0</Cy>
        <focalLength>0.0</focalLength>
      </plugin>
    </sensor>
  </gazebo>
  <material name="black">
    <color rgba="0.0 0.0 0.0 1.0"/>
  </material>
  <material name="blue">
    <color rgba="0.0 0.0 0.8 1.0"/>
  </material>
  <material name="BlueTransparent">
    <color rgba="0.0 0.0 0.8 0.3"/>
  </material>
  <material name="green">
    <color rgba="0.0 0.8 0.0 1.0"/>
  </material>
  <material name="grey">
    <color rgba="0.3 0.3 0.3 1.0"/>
  </material>
  <material name="orange">
    <color rgba="1.0 0.4235294117647059 0.0392156862745098 1.0"/>
  </material>
  <material name="brown">
    <color rgba="0.8705882352941177 0.8117647058823529 0.7647058823529411 1.0"/>
  </material>
  <material name="red">
    <color rgba="0.8 0.0 0.0 1.0"/>
  </material>
  <material name="white">
    <color rgba="1.0 1.0 1.0 1.0"/>
  </material>
  <material name="DarkGrey">
    <color rgba="0.175 0.175 0.175 1.0"/>
  </material>
  <!-- Base Link -->
  <link name="SAR_Body">
    <collision name="Body_Collision">
      <origin rpy="0 0 0" xyz="0 0 20.5e-3"/>
      <geometry>
        <!-- <cylinder radius="77.0e-3" length="41.0e-3"/> -->
        <box size="300e-3 350e-3 41.0e-3"/>
      </geometry>
    </collision>
    <visual>
      <origin rpy="0 0 0" xyz="0 0 0"/>
      <geometry>
        <mesh filename="package://sar_gazebo/models/Source_One/meshes/SO_V5_Base_Assembly.STL"/>
      </geometry>
      <material name="DarkGrey"/>
    </visual>
    <visual>
      <origin rpy="0 0 0" xyz="0 0 0"/>
      <geometry>
        <mesh filename="package://sar_gazebo/models/Source_One/meshes/SO_V5_Prop_Guard_Standoffs.STL"/>
      </geometry>
      <material name="DarkGrey"/>
    </visual>
    <inertial>
      <origin rpy="0 0 0" xyz="0 0 0"/>
      <mass value="693.0e-3"/>
      <inertia ixx="3.17e-3" ixy="0.0" ixz="0.0" iyy="2.71e-3" iyz="0.0" izz="5.27e-3"/>
    </inertial>
  </link>
  <link name="Prop_Guards">
    <visual>
      <origin rpy="0 0 0" xyz="0 0 0"/>
      <geometry>
        <mesh filename="package://sar_gazebo/models/Source_One/meshes/SO_V5_Prop_Guards.STL"/>
      </geometry>
      <material name="white"/>
    </visual>
    <inertial>
      <origin rpy="0 0 0" xyz="0 0 0"/>
      <mass value="1.0e-5"/>
      <inertia ixx="1.0e-6" ixy="0.0" ixz="0.0" iyy="1.0e-6" iyz="0.0" izz="1.0e-6"/>
    </inertial>
  </link>
  <joint name="Prop_Guard_Joint" type="fixed">
    <origin rpy="0 0 0" xyz="0 0 0"/>
    <parent link="SAR_Body"/>
    <child link="Prop_Guards"/>
  </joint>
  <joint name="Prop_1_Joint" type="continuous">
    <parent link="SAR_Body"/>
    <child link="Prop_1"/>
    <origin rpy="0 0 0" xyz="0.0726 -0.0866 0.028"/>
    <axis xyz="0 0 1"/>
  </joint>
  <link name="Prop_1">
    <visual>
      <origin rpy="0 0 0" xyz="0 0 0"/>
      <geometry>
        <mesh filename="package://sar_gazebo/models/Source_One/meshes/SO_V5_Propeller.STL"/>
      </geometry>
      <material name="BlueTransparent"/>
    </visual>
    <inertial>
      <origin rpy="0 0 0" xyz="0 0 0"/>
      <mass value="1.0e-5"/>
      <inertia ixx="1.0e-6" ixy="0.0" ixz="0.0" iyy="1.0e-6" iyz="0.0" izz="1.0e-6"/>
    </inertial>
  </link>
  <joint name="Prop_2_Joint" type="continuous">
    <parent link="SAR_Body"/>
    <child link="Prop_2"/>
    <origin rpy="0 0 0" xyz="-0.0726 -0.0866 0.028"/>
    <axis xyz="0 0 1"/>
  </joint>
  <link name="Prop_2">
    <visual>
      <origin rpy="0 0 0" xyz="0 0 0"/>
      <geometry>
        <mesh filename="package://sar_gazebo/models/Source_One/meshes/SO_V5_Propeller.STL"/>
      </geometry>
      <material name="BlueTransparent"/>
    </visual>
    <inertial>
      <origin rpy="0 0 0" xyz="0 0 0"/>
      <mass value="1.0e-5"/>
      <inertia ixx="1.0e-6" ixy="0.0" ixz="0.0" iyy="1.0e-6" iyz="0.0" izz="1.0e-6"/>
    </inertial>
  </link>
  <joint name="Prop_3_Joint" type="continuous">
    <parent link="SAR_Body"/>
    <child link="Prop_3"/>
    <origin rpy="0 0 0" xyz="-0.0726 0.0866 0.028"/>
    <axis xyz="0 0 1"/>
  </joint>
  <link name="Prop_3">
    <visual>
      <origin rpy="0 0 0" xyz="0 0 0"/>
      <geometry>
        <mesh filename="package://sar_gazebo/models/Source_One/meshes/SO_V5_Propeller.STL"/>
      </geometry>
      <material name="BlueTransparent"/>
    </visual>
    <inertial>
      <origin rpy="0 0 0" xyz="0 0 0"/>
      <mass value="1.0e-5"/>
      <inertia ixx="1.0e-6" ixy="0.0" ixz="0.0" iyy="1.0e-6" iyz="0.0" izz="1.0e-6"/>
    </inertial>
  </link>
  <joint name="Prop_4_Joint" type="continuous">
    <parent link="SAR_Body"/>
    <child link="Prop_4"/>
    <origin rpy="0 0 0" xyz="0.0726 0.0866 0.028"/>
    <axis xyz="0 0 1"/>
  </joint>
  <link name="Prop_4">
    <visual>
      <origin rpy="0 0 0" xyz="0 0 0"/>
      <geometry>
        <mesh filename="package://sar_gazebo/models/Source_One/meshes/SO_V5_Propeller.STL"/>
      </geometry>
      <material name="BlueTransparent"/>
    </visual>
    <inertial>
      <origin rpy="0 0 0" xyz="0 0 0"/>
      <mass value="1.0e-5"/>
      <inertia ixx="1.0e-6" ixy="0.0" ixz="0.0" iyy="1.0e-6" iyz="0.0" izz="1.0e-6"/>
    </inertial>
  </link>
  <link name="Leg_1">
    <visual>
      <geometry>
        <mesh filename="package://sar_gazebo/models/Source_One/meshes/Leg_Assembly_60_deg--250mm.STL"/>
      </geometry>
      <material name="red"/>
    </visual>
    <inertial>
      <origin rpy="0 0 0" xyz="0 0 0"/>
      <mass value="2.6e-2"/>
      <inertia ixx="1.53e-6" ixy="0.0" ixz="0.0" iyy="3.27e-4" iyz="0.0" izz="3.28e-4"/>
    </inertial>
    <collision>
      <origin rpy="0 0 0" xyz="259.6e-3 0 -2.3e-3"/>
      <geometry>
        <sphere radius="13.9e-3"/>
      </geometry>
    </collision>
  </link>
  <joint name="Hinge_1_Joint" type="fixed">
    <origin rpy="0 0.524 -0.785" xyz="0.0185 -0.0185 -0.004"/>
    <parent link="SAR_Body"/>
    <child link="Leg_1"/>
  </joint>
  <link name="Leg_2">
    <visual>
      <geometry>
        <mesh filename="package://sar_gazebo/models/Source_One/meshes/Leg_Assembly_60_deg--250mm.STL"/>
      </geometry>
      <material name="grey"/>
    </visual>
    <inertial>
      <origin rpy="0 0 0" xyz="0 0 0"/>
      <mass value="2.6e-2"/>
      <inertia ixx="1.53e-6" ixy="0.0" ixz="0.0" iyy="3.27e-4" iyz="0.0" izz="3.28e-4"/>
    </inertial>
    <collision>
      <origin rpy="0 0 0" xyz="259.6e-3 0 -2.3e-3"/>
      <geometry>
        <sphere radius="13.9e-3"/>
      </geometry>
    </collision>
  </link>
  <joint name="Hinge_2_Joint" type="fixed">
    <origin rpy="0 0.524 -2.35" xyz="-0.0185 -0.0185 -0.004"/>
    <parent link="SAR_Body"/>
    <child link="Leg_2"/>
  </joint>
  <link name="Leg_3">
    <visual>
      <geometry>
        <mesh filename="package://sar_gazebo/models/Source_One/meshes/Leg_Assembly_60_deg--250mm.STL"/>
      </geometry>
      <material name="grey"/>
    </visual>
    <inertial>
      <origin rpy="0 0 0" xyz="0 0 0"/>
      <mass value="2.6e-2"/>
      <inertia ixx="1.53e-6" ixy="0.0" ixz="0.0" iyy="3.27e-4" iyz="0.0" izz="3.28e-4"/>
    </inertial>
    <collision>
      <origin rpy="0 0 0" xyz="259.6e-3 0 -2.3e-3"/>
      <geometry>
        <sphere radius="13.9e-3"/>
      </geometry>
    </collision>
  </link>
  <joint name="Hinge_3_Joint" type="fixed">
    <origin rpy="0 0.524 2.35" xyz="-0.0185 0.0185 -0.004"/>
    <parent link="SAR_Body"/>
    <child link="Leg_3"/>
  </joint>
  <link name="Leg_4">
    <visual>
      <geometry>
        <mesh filename="package://sar_gazebo/models/Source_One/meshes/Leg_Assembly_60_deg--250mm.STL"/>
      </geometry>
      <material name="red"/>
    </visual>
    <inertial>
      <origin rpy="0 0 0" xyz="0 0 0"/>
      <mass value="2.6e-2"/>
      <inertia ixx="1.53e-6" ixy="0.0" ixz="0.0" iyy="3.27e-4" iyz="0.0" izz="3.28e-4"/>
    </inertial>
    <collision>
      <origin rpy="0 0 0" xyz="259.6e-3 0 -2.3e-3"/>
      <geometry>
        <sphere radius="13.9e-3"/>
      </geometry>
    </collision>
  </link>
  <joint name="Hinge_4_Joint" type="fixed">
    <origin rpy="0 0.524 0.785" xyz="0.0185 0.0185 -0.004"/>
    <parent link="SAR_Body"/>
    <child link="Leg_4"/>
  </joint>
  <!-- Camera -->
  <link name="camera_link">
    <visual>
      <origin rpy="0 0 0" xyz="0 0 0"/>
      <geometry>
        <box size="0.015 0.015 0.015"/>
      </geometry>
      <material name="grey"/>
    </visual>
    <inertial>
      <mass value="1e-5"/>
      <origin rpy="0 0 0" xyz="0 0 0"/>
      <inertia ixx="1e-6" ixy="0" ixz="0" iyy="1e-6" iyz="0" izz="1e-6"/>
    </inertial>
  </link>
  <joint name="camera_joint" type="fixed">
    <origin rpy="0 0 0" xyz="0.07 0 0.02"/>
    <parent link="SAR_Body"/>
    <child link="camera_link"/>
  </joint>
  <!-- generate an optical frame http://www.ros.org/reps/rep-0103.html#suffix-frames
      so that ros and opencv can operate on the camera frame correctly -->
  <joint name="camera_optical_joint" type="fixed">
    <!-- these values have to be these values otherwise the gazebo camera image
        won't be aligned properly with the frame it is supposedly originating from -->
    <origin rpy="-1.5707963267948966 0 -1.5707963267948966" xyz="0 0 0"/>
    <parent link="camera_link"/>
    <child link="camera_link_optical"/>
  </joint>
  <link name="camera_link_optical">
  </link>
  <gazebo>
    <plugin filename="libgazebo_ros_joint_state_publisher.so" name="joint_state_publisher">
      <jointName>Prop_1_Joint,Prop_2_Joint,Prop_3_Joint,Prop_4_Joint</jointName>
      <updateRate>100.0</updateRate>
      <alwaysOn>true</alwaysOn>
    </plugin>
  </gazebo>
  <joint name="velodyne_base_mount_joint" type="fixed">
    <origin rpy="0 0 0" xyz="0.025 0 0.07"/>
    <parent link="SAR_Body"/>
    <child link="velodyne_base_link"/>
  </joint>
  <link name="velodyne_base_link">
    <inertial>
      <mass value="1e-5"/>
      <origin rpy="0 0 0" xyz="0 0 0"/>
      <inertia ixx="1e-6" ixy="0" ixz="0" iyy="1e-6" iyz="0" izz="1e-6"/>
    </inertial>
    <visual>
      <geometry>
        <mesh filename="package://velodyne_description/meshes/VLP16_base_1.dae" scale="0.35 0.35 0.35"/>
      </geometry>
    </visual>
    <visual>
      <geometry>
        <mesh filename="package://velodyne_description/meshes/VLP16_base_2.dae" scale="0.35 0.35 0.35"/>
      </geometry>
    </visual>
  </link>
  <joint name="velodyne_base_scan_joint" type="fixed">
    <origin rpy="0 0 0" xyz="0 0 0.0377"/>
    <parent link="velodyne_base_link"/>
    <child link="velodyne"/>
  </joint>
  <link name="velodyne">
    <inertial>
      <mass value="0.01"/>
      <origin xyz="0 0 0"/>
      <inertia ixx="1e-7" ixy="0" ixz="0" iyy="1e-7" iyz="0" izz="1e-7"/>
    </inertial>
    <visual>
      <origin xyz="0 0 -0.0377"/>
      <geometry>
        <mesh filename="package://velodyne_description/meshes/VLP16_scan.dae" scale="0.35 0.35 0.35"/>
      </geometry>
    </visual>
  </link>
  <!-- Gazebo requires the velodyne_gazebo_plugins package -->
  <gazebo reference="velodyne">
    <sensor name="velodyne-VLP16" type="gpu_ray">
      <pose>0 0 0 0 0 0</pose>
      <visualize>false</visualize>
      <update_rate>30</update_rate>
      <ray>
        <scan>
          <horizontal>
            <samples>1875</samples>
            <resolution>1</resolution>
            <min_angle>-3.141592653589793</min_angle>
            <max_angle>3.141592653589793</max_angle>
          </horizontal>
          <vertical>
            <samples>32</samples>
            <resolution>1</resolution>
            <min_angle>-0.2617993877991494</min_angle>
            <max_angle> 0.5235987755982988</max_angle>
          </vertical>
        </scan>
        <range>
          <min>0.1</min>
          <max>131.0</max>
          <resolution>0.001</resolution>
        </range>
        <noise>
          <type>gaussian</type>
          <mean>0.0</mean>
          <stddev>0.0</stddev>
        </noise>
      </ray>
      <plugin filename="libgazebo_ros_velodyne_gpu_laser.so" name="gazebo_ros_laser_controller">
        <topicName>/velodyne_points</topicName>
        <frameName>velodyne</frameName>
        <min_range>0.1</min_range>
        <max_range>130.0</max_range>
        <gaussianNoise>0.0</gaussianNoise>
      </plugin>
    </sensor>
  </gazebo>
</robot>
