<?xml version="1.0"?>
<!-- Revolute-Revolute Manipulator -->
<robot name="Source_One"
  xmlns:xacro="http://www.ros.org/wiki/xacro">

  <!-- Constants for robot dimensions -->
  <xacro:property name="PI" value="3.1415926535897931"/>

  <xacro:property name="prop_x_offset" value="72.6e-3" />
  <xacro:property name="prop_y_offset" value="86.6e-3" />
  <xacro:property name="prop_z_offset" value="28.0e-3" />

  <xacro:property name="leg_x_offset" value="18.5e-3" />
  <xacro:property name="leg_y_offset" value="18.5e-3" />
  <xacro:property name="leg_z_offset" value="-4.0e-3" />

  <xacro:property name="leg_pitch"    value="0.524" />
  <xacro:property name="leg_yaw"      value="0.785" />




  <xacro:property name="camera_link" value="0.015" />




  <!-- Import all Gazebo-customization elements, including Gazebo colors -->
  <xacro:include filename="$(find sar_gazebo)/models/Source_One/urdf/Source_One.gazebo" />
  <!-- Import Rviz colors -->
  <xacro:include filename="$(find sar_gazebo)/models/Source_One/urdf/materials.xacro" />



  <!-- Base Link -->
  <link name="SAR_Body">
    <collision name="Body_Collision">
      <origin xyz="0 0 20.5e-3" rpy="0 0 0"/>
      <geometry>
        <!-- <cylinder radius="77.0e-3" length="41.0e-3"/> -->
        <box size="300e-3 350e-3 41.0e-3"/>
      </geometry>
    </collision>

    <visual>
      <origin xyz="0 0 0" rpy="0 0 0"/>
      <geometry>
        <mesh filename="package://sar_gazebo/models/Source_One/meshes/SO_V5_Base_Assembly.STL"/>
      </geometry>
      <material name="DarkGrey"/>
    </visual>

    <visual>
      <origin xyz="0 0 0" rpy="0 0 0"/>
      <geometry>
        <mesh filename="package://sar_gazebo/models/Source_One/meshes/SO_V5_Prop_Guard_Standoffs.STL"/>
      </geometry>
      <material name="DarkGrey"/>
    </visual>

    <inertial>
      <origin xyz="0 0 0" rpy="0 0 0"/>
      <mass value="693.0e-3"/>
      <inertia ixx="3.17e-3" iyy="2.71e-3" izz="5.27e-3" ixy="0.0" ixz="0.0" iyz="0.0" />
    </inertial>
  </link>

  <link name="Prop_Guards">
    <visual>
      <origin xyz="0 0 0" rpy="0 0 0"/>
      <geometry>
        <mesh filename="package://sar_gazebo/models/Source_One/meshes/SO_V5_Prop_Guards.STL"/>
      </geometry>
      <material name="white"/>
    </visual>

    <inertial>
      <origin xyz="0 0 0" rpy="0 0 0"/>
      <mass value="1.0e-5"/>
      <inertia ixx="1.0e-6" iyy="1.0e-6" izz="1.0e-6" ixy="0.0" ixz="0.0" iyz="0.0" />
    </inertial>
  </link>

  <joint name="Prop_Guard_Joint" type="fixed">
    <origin xyz="0 0 0" rpy="0 0 0"/>
    <parent link="SAR_Body"/>
    <child link="Prop_Guards"/>
  </joint>


  <joint name="Prop_1_Joint" type="continuous">
    <parent link="SAR_Body"/>
    <child link="Prop_1"/>
    <origin xyz="${prop_x_offset} -${prop_y_offset} ${prop_z_offset}" rpy="0 0 0"/>
    <axis xyz="0 0 1"/>
  </joint>

  <link name="Prop_1">
    <visual>
      <origin xyz="0 0 0" rpy="0 0 0"/>
      <geometry>
        <mesh filename="package://sar_gazebo/models/Source_One/meshes/SO_V5_Propeller.STL"/>
      </geometry>
      <material name="BlueTransparent"/>
    </visual>

    <inertial>
      <origin xyz="0 0 0" rpy="0 0 0"/>
      <mass value="1.0e-5"/>
      <inertia ixx="1.0e-6" iyy="1.0e-6" izz="1.0e-6" ixy="0.0" ixz="0.0" iyz="0.0" />
    </inertial>
  </link>

  <joint name="Prop_2_Joint" type="continuous">
    <parent link="SAR_Body"/>
    <child link="Prop_2"/>
    <origin xyz="-${prop_x_offset} -${prop_y_offset} ${prop_z_offset}" rpy="0 0 0"/>
    <axis xyz="0 0 1"/>
  </joint>

  <link name="Prop_2">
    <visual>
      <origin xyz="0 0 0" rpy="0 0 0"/>
      <geometry>
        <mesh filename="package://sar_gazebo/models/Source_One/meshes/SO_V5_Propeller.STL"/>
      </geometry>
      <material name="BlueTransparent"/>
    </visual>

    <inertial>
      <origin xyz="0 0 0" rpy="0 0 0"/>
      <mass value="1.0e-5"/>
      <inertia ixx="1.0e-6" iyy="1.0e-6" izz="1.0e-6" ixy="0.0" ixz="0.0" iyz="0.0" />
    </inertial>
  </link>

  <joint name="Prop_3_Joint" type="continuous">
    <parent link="SAR_Body"/>
    <child link="Prop_3"/>
    <origin xyz="-${prop_x_offset} ${prop_y_offset} ${prop_z_offset}" rpy="0 0 0"/>
    <axis xyz="0 0 1"/>
  </joint>

  <link name="Prop_3">
    <visual>
      <origin xyz="0 0 0" rpy="0 0 0"/>
      <geometry>
        <mesh filename="package://sar_gazebo/models/Source_One/meshes/SO_V5_Propeller.STL"/>
      </geometry>
      <material name="BlueTransparent"/>
    </visual>

    <inertial>
      <origin xyz="0 0 0" rpy="0 0 0"/>
      <mass value="1.0e-5"/>
      <inertia ixx="1.0e-6" iyy="1.0e-6" izz="1.0e-6" ixy="0.0" ixz="0.0" iyz="0.0" />
    </inertial>
  </link>

  <joint name="Prop_4_Joint" type="continuous">
    <parent link="SAR_Body"/>
    <child link="Prop_4"/>
    <origin xyz="${prop_x_offset} ${prop_y_offset} ${prop_z_offset}" rpy="0 0 0"/>
    <axis xyz="0 0 1"/>
  </joint>

  <link name="Prop_4">
    <visual>
      <origin xyz="0 0 0" rpy="0 0 0"/>
      <geometry>
        <mesh filename="package://sar_gazebo/models/Source_One/meshes/SO_V5_Propeller.STL"/>
      </geometry>
      <material name="BlueTransparent"/>
    </visual>

    <inertial>
      <origin xyz="0 0 0" rpy="0 0 0"/>
      <mass value="1.0e-5"/>
      <inertia ixx="1.0e-6" iyy="1.0e-6" izz="1.0e-6" ixy="0.0" ixz="0.0" iyz="0.0" />
    </inertial>
  </link>

  <link name="Leg_1">
    <visual>
      <geometry>
        <mesh filename="package://sar_gazebo/models/Source_One/meshes/Leg_Assembly_60_deg--250mm.STL"/>
      </geometry>
      <material name="red"/>
    </visual>

    <inertial>
      <origin xyz="0 0 0" rpy="0 0 0"/>
      <mass value="2.6e-2"/>
      <inertia ixx="1.53e-6" iyy="3.27e-4" izz="3.28e-4" ixy="0.0" ixz="0.0" iyz="0.0" />
    </inertial>

    <collision>
      <origin xyz="259.6e-3 0 -2.3e-3" rpy="0 0 0"/>
      <geometry>
        <sphere radius="13.9e-3"/>
      </geometry>
    
    </collision>
  </link>

  <joint name="Hinge_1_Joint" type="fixed">
    <origin xyz="${leg_x_offset} -${leg_y_offset} ${leg_z_offset}" rpy="0 ${leg_pitch} -0.785"/>
    <parent link="SAR_Body"/>
    <child link="Leg_1"/>
  </joint>

  <link name="Leg_2">
    <visual>
      <geometry>
        <mesh filename="package://sar_gazebo/models/Source_One/meshes/Leg_Assembly_60_deg--250mm.STL"/>
      </geometry>
      <material name="grey"/>
    </visual>

    <inertial>
      <origin xyz="0 0 0" rpy="0 0 0"/>
      <mass value="2.6e-2"/>
      <inertia ixx="1.53e-6" iyy="3.27e-4" izz="3.28e-4" ixy="0.0" ixz="0.0" iyz="0.0" />
    </inertial>

    <collision>
      <origin xyz="259.6e-3 0 -2.3e-3" rpy="0 0 0"/>
      <geometry>
        <sphere radius="13.9e-3"/>
      </geometry>
    
    </collision>
  </link>

  <joint name="Hinge_2_Joint" type="fixed">
    <origin xyz="-${leg_x_offset} -${leg_y_offset} ${leg_z_offset}" rpy="0 ${leg_pitch} -2.35"/>
    <parent link="SAR_Body"/>
    <child link="Leg_2"/>
  </joint>

  <link name="Leg_3">
    <visual>
      <geometry>
        <mesh filename="package://sar_gazebo/models/Source_One/meshes/Leg_Assembly_60_deg--250mm.STL"/>
      </geometry>
      <material name="grey"/>
    </visual>

    <inertial>
      <origin xyz="0 0 0" rpy="0 0 0"/>
      <mass value="2.6e-2"/>
      <inertia ixx="1.53e-6" iyy="3.27e-4" izz="3.28e-4" ixy="0.0" ixz="0.0" iyz="0.0" />
    </inertial>

    <collision>
      <origin xyz="259.6e-3 0 -2.3e-3" rpy="0 0 0"/>
      <geometry>
        <sphere radius="13.9e-3"/>
      </geometry>
    
    </collision>
  </link>

  <joint name="Hinge_3_Joint" type="fixed">
    <origin xyz="-${leg_x_offset} ${leg_y_offset} ${leg_z_offset}" rpy="0 ${leg_pitch} 2.35"/>
    <parent link="SAR_Body"/>
    <child link="Leg_3"/>
  </joint>

  <link name="Leg_4">
    <visual>
      <geometry>
        <mesh filename="package://sar_gazebo/models/Source_One/meshes/Leg_Assembly_60_deg--250mm.STL"/>
      </geometry>
      <material name="red"/>
    </visual>

    <inertial>
      <origin xyz="0 0 0" rpy="0 0 0"/>
      <mass value="2.6e-2"/>
      <inertia ixx="1.53e-6" iyy="3.27e-4" izz="3.28e-4" ixy="0.0" ixz="0.0" iyz="0.0" />
    </inertial>

    <collision>
      <origin xyz="259.6e-3 0 -2.3e-3" rpy="0 0 0"/>
      <geometry>
        <sphere radius="13.9e-3"/>
      </geometry>
    
    </collision>
  </link>

  <joint name="Hinge_4_Joint" type="fixed">
    <origin xyz="${leg_x_offset} ${leg_y_offset} ${leg_z_offset}" rpy="0 ${leg_pitch} 0.785"/>
    <parent link="SAR_Body"/>
    <child link="Leg_4"/>
  </joint>

  

  <!-- Camera -->
  <link name="camera_link">
    <visual>
      <origin xyz="0 0 0" rpy="0 0 0"/>
      <geometry>
        <box size="${camera_link} ${camera_link} ${camera_link}"/>
      </geometry>
      <material name="grey"/>
    </visual>

    <inertial>
      <mass value="1e-5" />
      <origin xyz="0 0 0" rpy="0 0 0"/>
      <inertia ixx="1e-6" ixy="0" ixz="0" iyy="1e-6" iyz="0" izz="1e-6" />
    </inertial>
  </link>

  <joint name="camera_joint" type="fixed">
    <origin xyz="0.07 0 0.02" rpy="0 0 0"/>
    <parent link="SAR_Body"/>
    <child link="camera_link"/>
  </joint>

  <!-- generate an optical frame http://www.ros.org/reps/rep-0103.html#suffix-frames
      so that ros and opencv can operate on the camera frame correctly -->
  <joint name="camera_optical_joint" type="fixed">
    <!-- these values have to be these values otherwise the gazebo camera image
        won't be aligned properly with the frame it is supposedly originating from -->
    <origin xyz="0 0 0" rpy="${-pi/2} 0 ${-pi/2}"/>
    <parent link="camera_link"/>
    <child link="camera_link_optical"/>
  </joint>

  <link name="camera_link_optical">
  </link>



  <gazebo>
    <plugin name="joint_state_publisher" filename="libgazebo_ros_joint_state_publisher.so">
      <jointName>Prop_1_Joint,Prop_2_Joint,Prop_3_Joint,Prop_4_Joint</jointName>
      <updateRate>100.0</updateRate>
      <alwaysOn>true</alwaysOn>
    </plugin>
  </gazebo>


  <xacro:include filename="$(find velodyne_description)/urdf/VLP-16.urdf.xacro"/>
  <xacro:VLP-16 parent="SAR_Body" name="velodyne" topic="/velodyne_points" hz="30" lasers="32" gpu="true" collision_range="0.1" min_range="0.1" max_range="130.0" noise="0.0">
    <origin xyz="0.025 0 0.07" rpy="0 0 0" />
  </xacro:VLP-16>




</robot>
